Workbook

Sheet Վաճառքի կանխատեսում 2014-2018
B1: Նշել ընկերության անունը
B2: Վաճառքի կանխատեսում 2014թ.
A3: հ/հ | B3: Համախառն վաճառք | C3: Հունվար | F3: Փետրվար | I3: Մարտ | L3: Ապրիլ | O3: Մայիս | R3: Հունիս | U3: Հուլիս | X3: Օգոստոս | AA3: Սեպտեմբեր | AD3: Հոկտեմբեր | AG3: Նոյեմբեր | AJ3: Դեկտեմբեր | AM3: ՀԱՆՐԱԳՈՒՄԱՐ
A4: 1 | C4: միավորի գին | D4: քանակ | E4: ընդամենը | F4: միավորի գին | G4: քանակ | H4: ընդամենը | I4: միավորի գին | J4: քանակ | K4: ընդամենը | L4: միավորի գին | M4: քանակ | N4: ընդամենը | O4: միավորի գին | P4: քանակ | Q4: ընդամենը | R4: միավորի գին | S4: քանակ | T4: ընդամենը | U4: միավորի գին | V4: քանակ | W4: ընդամենը | X4: միավորի գին | Y4: քանակ | Z4: ընդամենը | AA4: միավորի գին | AB4: քանակ | AC4: ընդամենը | AD4: միավորի գին | AE4: քանակ | AF4: ընդամենը | AG4: միավորի գին | AH4: քանակ | AI4: ընդամենը | AJ4: միավորի գին | AK4: քանակ | AL4: ընդամենը | AM4: միավորի գին | AN4: քանակ | AO4: ընդամենը
A5: 2 | B5: Մետաքսե բարձի երես | C5: 25 000,00 | D5: 10 | E5: 125 000,00 | F5: 25 000,00 | G5: 15,00 | H5: 375 000,00 | I5: 25 000,00 | J5: 40,00 | K5: 1 000 000,00 | L5: 25 000,00 | M5: 25,00 | N5: 625 000,00 | O5: 25 000,00 | P5: 20,00 | Q5: 500 000,00 | R5: 25 000,00 | S5: 22,00 | T5: 550 000,00 | U5: 25 000,00 | V5: 25,00 | W5: 625 000,00 | X5: 25 000,00 | Y5: 25,00 | Z5: 625 000,00 | AA5: 25 000,00 | AB5: 30,00 | AC5: 750 000,00 | AD5: 25 000,00 | AE5: 35,00 | AF5: 875 000,00 | AG5: 25 000,00 | AH5: 45,00 | AI5: 1 125 000,00 | AJ5: 25 000,00 | AK5: 60,00 | AL5: 1 500 000,00 | AM5: 25 000,00 | AN5: 347,00 | AO5: 8 675 000,00
A6: 3 | B6: Մետաքսե քնի դիմակ | C6: 10 000,00 | D6: 10 | E6: 50 000,00 | F6: 10 000,00 | G6: 10,00 | H6: 100 000,00 | I6: 10 000,00 | J6: 50,00 | K6: 500 000,00 | L6: 10 000,00 | M6: 35,00 | N6: 350 000,00 | O6: 10 000,00 | P6: 25,00 | Q6: 250 000,00 | R6: 10 000,00 | S6: 30,00 | T6: 300 000,00 | U6: 10 000,00 | V6: 35,00 | W6: 350 000,00 | X6: 10 000,00 | Y6: 30,00 | Z6: 300 000,00 | AA6: 10 000,00 | AB6: 40,00 | AC6: 400 000,00 | AD6: 10 000,00 | AE6: 45,00 | AF6: 450 000,00 | AG6: 10 000,00 | AH6: 60,00 | AI6: 600 000,00 | AJ6: 10 000,00 | AK6: 85,00 | AL6: 850 000,00 | AM6: 10 000,00 | AN6: 450,00 | AO6: 4 500 000,00
A7: 4 | B7: Մետաքսե մազակալ | C7: 5 000,00 | D7: 20 | E7: 125 000,00 | F7: 5 000,00 | G7: 50,00 | H7: 250 000,00 | I7: 5 000,00 | J7: 80,00 | K7: 400 000,00 | L7: 5 000,00 | M7: 50,00 | N7: 250 000,00 | O7: 5 000,00 | P7: 40,00 | Q7: 200 000,00 | R7: 5 000,00 | S7: 45,00 | T7: 225 000,00 | U7: 5 000,00 | V7: 50,00 | W7: 250 000,00 | X7: 5 000,00 | Y7: 50,00 | Z7: 250 000,00 | AA7: 5 000,00 | AB7: 60,00 | AC7: 300 000,00 | AD7: 5 000,00 | AE7: 70,00 | AF7: 350 000,00 | AG7: 5 000,00 | AH7: 90,00 | AI7: 450 000,00 | AJ7: 5 000,00 | AK7: 130,00 | AL7: 650 000,00 | AM7: 5 000,00 | AN7: 740,00 | AO7: 3 700 000,00
A8: 5 | B8: Արտադրանք/ծառայություն 4 | C8: 0,00 | D8: 0,00 | E8: 0,00 | F8: 0,00 | G8: 0,00 | H8: 0,00 | I8: 0,00 | J8: 0,00 | K8: 0,00 | L8: 0,00 | M8: 0,00 | N8: 0,00 | O8: 0,00 | P8: 0,00 | Q8: 0,00 | R8: 0,00 | S8: 0,00 | T8: 0,00 | U8: 0,00 | V8: 0,00 | W8: 0,00 | X8: 0,00 | Y8: 0,00 | Z8: 0,00 | AA8: 0,00 | AB8: 0,00 | AC8: 0,00 | AD8: 0,00 | AE8: 0,00 | AF8: 0,00 | AG8: 0,00 | AH8: 0,00 | AI8: 0,00 | AJ8: 0,00 | AK8: 0,00 | AL8: 0,00 | AM8: 0,00 | AN8: 0,00 | AO8: 0,00
A9: 6 | B9: Արտադրանք/ծառայություն 5 | C9: 0,00 | D9: 0,00 | E9: 0,00 | F9: 0,00 | G9: 0,00 | H9: 0,00 | I9: 0,00 | J9: 0,00 | K9: 0,00 | L9: 0,00 | M9: 0,00 | N9: 0,00 | O9: 0,00 | P9: 0,00 | Q9: 0,00 | R9: 0,00 | S9: 0,00 | T9: 0,00 | U9: 0,00 | V9: 0,00 | W9: 0,00 | X9: 0,00 | Y9: 0,00 | Z9: 0,00 | AA9: 0,00 | AB9: 0,00 | AC9: 0,00 | AD9: 0,00 | AE9: 0,00 | AF9: 0,00 | AG9: 0,00 | AH9: 0,00 | AI9: 0,00 | AJ9: 0,00 | AK9: 0,00 | AL9: 0,00 | AM9: 0,00 | AN9: 0,00 | AO9: 0,00
A10: 7 | B10: ԸՆԴԱՄԵՆԸ | D10: 35,00 | E10: 300 000,00 | G10: 75,00 | H10: 725 000,00 | J10: 170,00 | K10: 1 900 000,00 | M10: 110,00 | N10: 1 225 000,00 | P10: 85,00 | Q10: 950 000,00 | S10: 97,00 | T10: 1 075 000,00 | V10: 110,00 | W10: 1 225 000,00 | Y10: 105,00 | Z10: 1 175 000,00 | AB10: 130,00 | AC10: 1 450 000,00 | AE10: 150,00 | AF10: 1 675 000,00 | AH10: 195,00 | AI10: 2 175 000,00 | AK10: 275,00 | AL10: 3 000 000,00 | AN10: 1 537,00 | AO10: 16 875 000,00
B12: Նշել ընկերության անունը
B13: Վաճառքի կանխատեսում 2015թ.
A14: հ/հ | B14: Համախառն վաճառք | C14: Հունվար | F14: Փետրվար | I14: Մարտ | L14: Ապրիլ | O14: Մայիս | R14: Հունիս | U14: Հուլիս | X14: Օգոստոս | AA14: Սեպտեմբեր | AD14: Հոկտեմբեր | AG14: Նոյեմբեր | AJ14: Դեկտեմբեր | AM14: ՀԱՆՐԱԳՈՒՄԱՐ
A15: 1 | C15: միավորի գին | D15: քանակ | E15: ընդամենը | F15: միավորի գին | G15: քանակ | H15: ընդամենը | I15: միավորի գին | J15: քանակ | K15: ընդամենը | L15: միավորի գին | M15: քանակ | N15: ընդամենը | O15: միավորի գին | P15: քանակ | Q15: ընդամենը | R15: միավորի գին | S15: քանակ | T15: ընդամենը | U15: միավորի գին | V15: քանակ | W15: ընդամենը | X15: միավորի գին | Y15: քանակ | Z15: ընդամենը | AA15: միավորի գին | AB15: քանակ | AC15: ընդամենը | AD15: միավորի գին | AE15: քանակ | AF15: ընդամենը | AG15: միավորի գին | AH15: քանակ | AI15: ընդամենը | AJ15: միավորի գին | AK15: քանակ | AL15: ընդամենը | AM15: միավորի գին | AN15: քանակ | AO15: ընդամենը
A16: 2 | B16: Մետաքսե բարձի երես | C16: 25 000,00 | D16: 15,00 | E16: 375 000,00 | F16: 25 000,00 | G16: 30,00 | H16: 750 000,00 | I16: 25 000,00 | J16: 50,00 | K16: 1 250 000,00 | L16: 25 000,00 | M16: 35,00 | N16: 875 000,00 | O16: 25 000,00 | P16: 25,00 | Q16: 625 000,00 | R16: 25 000,00 | S16: 28,00 | T16: 700 000,00 | U16: 25 000,00 | V16: 32,00 | W16: 800 000,00 | X16: 25 000,00 | Y16: 30,00 | Z16: 750 000,00 | AA16: 25 000,00 | AB16: 35,00 | AC16: 875 000,00 | AD16: 25 000,00 | AE16: 40,00 | AF16: 1 000 000,00 | AG16: 25 000,00 | AH16: 55,00 | AI16: 1 375 000,00 | AJ16: 25 000,00 | AK16: 75,00 | AL16: 1 875 000,00 | AM16: 25 000,00 | AN16: 450,00 | AO16: 11 250 000,00
A17: 3 | B17: Մետաքսե քնի դիմակ | C17: 10 000,00 | D17: 20,00 | E17: 200 000,00 | F17: 10 000,00 | G17: 45,00 | H17: 450 000,00 | I17: 10 000,00 | J17: 65,00 | K17: 650 000,00 | L17: 10 000,00 | M17: 45,00 | N17: 450 000,00 | O17: 10 000,00 | P17: 35,00 | Q17: 350 000,00 | R17: 10 000,00 | S17: 40,00 | T17: 400 000,00 | U17: 10 000,00 | V17: 45,00 | W17: 450 000,00 | X17: 10 000,00 | Y17: 40,00 | Z17: 400 000,00 | AA17: 10 000,00 | AB17: 50,00 | AC17: 500 000,00 | AD17: 10 000,00 | AE17: 55,00 | AF17: 550 000,00 | AG17: 10 000,00 | AH17: 75,00 | AI17: 750 000,00 | AJ17: 10 000,00 | AK17: 100,00 | AL17: 1 000 000,00 | AM17: 10 000,00 | AN17: 615,00 | AO17: 6 150 000,00
A18: 4 | B18: Մետաքսե մազակալ | C18: 5 000,00 | D18: 35,00 | E18: 175 000,00 | F18: 5 000,00 | G18: 65,00 | H18: 325 000,00 | I18: 5 000,00 | J18: 100,00 | K18: 500 000,00 | L18: 5 000,00 | M18: 60,00 | N18: 300 000,00 | O18: 5 000,00 | P18: 55,00 | Q18: 275 000,00 | R18: 5 000,00 | S18: 60,00 | T18: 300 000,00 | U18: 5 000,00 | V18: 65,00 | W18: 325 000,00 | X18: 5 000,00 | Y18: 60,00 | Z18: 300 000,00 | AA18: 5 000,00 | AB18: 75,00 | AC18: 375 000,00 | AD18: 5 000,00 | AE18: 85,00 | AF18: 425 000,00 | AG18: 5 000,00 | AH18: 110,00 | AI18: 550 000,00 | AJ18: 5 000,00 | AK18: 160,00 | AL18: 800 000,00 | AM18: 5 000,00 | AN18: 930,00 | AO18: 4 650 000,00
A19: 5 | B19: Արտադրանք/ծառայություն 4 | C19: 0,00 | D19: 0,00 | E19: 0,00 | F19: 0,00 | G19: 0,00 | H19: 0,00 | I19: 0,00 | J19: 0,00 | K19: 0,00 | L19: 0,00 | M19: 0,00 | N19: 0,00 | O19: 0,00 | P19: 0,00 | Q19: 0,00 | R19: 0,00 | S19: 0,00 | T19: 0,00 | U19: 0,00 | V19: 0,00 | W19: 0,00 | X19: 0,00 | Y19: 0,00 | Z19: 0,00 | AA19: 0,00 | AB19: 0,00 | AC19: 0,00 | AD19: 0,00 | AE19: 0,00 | AF19: 0,00 | AG19: 0,00 | AH19: 0,00 | AI19: 0,00 | AJ19: 0,00 | AK19: 0,00 | AL19: 0,00 | AM19: 0,00 | AN19: 0,00 | AO19: 0,00
A20: 6 | B20: Արտադրանք/ծառայություն 5 | C20: 0,00 | D20: 0,00 | E20: 0,00 | F20: 0,00 | G20: 0,00 | H20: 0,00 | I20: 0,00 | J20: 0,00 | K20: 0,00 | L20: 0,00 | M20: 0,00 | N20: 0,00 | O20: 0,00 | P20: 0,00 | Q20: 0,00 | R20: 0,00 | S20: 0,00 | T20: 0,00 | U20: 0,00 | V20: 0,00 | W20: 0,00 | X20: 0,00 | Y20: 0,00 | Z20: 0,00 | AA20: 0,00 | AB20: 0,00 | AC20: 0,00 | AD20: 0,00 | AE20: 0,00 | AF20: 0,00 | AG20: 0,00 | AH20: 0,00 | AI20: 0,00 | AJ20: 0,00 | AK20: 0,00 | AL20: 0,00 | AM20: 0,00 | AN20: 0,00 | AO20: 0,00
A21: 7 | B21: ԸՆԴԱՄԵՆԸ | D21: 70,00 | E21: 750 000,00 | G21: 140,00 | H21: 1 525 000,00 | J21: 215,00 | K21: 2 400 000,00 | M21: 140,00 | N21: 1 625 000,00 | P21: 115,00 | Q21: 1 250 000,00 | S21: 128,00 | T21: 1 400 000,00 | V21: 142,00 | W21: 1 575 000,00 | Y21: 130,00 | Z21: 1 450 000,00 | AB21: 160,00 | AC21: 1 750 000,00 | AE21: 180,00 | AF21: 1 975 000,00 | AH21: 240,00 | AI21: 2 675 000,00 | AK21: 335,00 | AL21: 3 675 000,00 | AN21: 1 995,00 | AO21: 22 050 000,00
B23: Նշել ընկերության անունը
B24: Վաճառքի կանխատեսում 2016թ.
A25: հ/հ | B25: Համախառն վաճառք | C25: Հունվար | F25: Փետրվար | I25: Մարտ | L25: Ապրիլ | O25: Մայիս | R25: Հունիս | U25: Հուլիս | X25: Օգոստոս | AA25: Սեպտեմբեր | AD25: Հոկտեմբեր | AG25: Նոյեմբեր | AJ25: Դեկտեմբեր | AM25: ՀԱՆՐԱԳՈՒՄԱՐ
A26: 1 | C26: միավորի գին | D26: քանակ | E26: ընդամենը | F26: միավորի գին | G26: քանակ | H26: ընդամենը | I26: միավորի գին | J26: քանակ | K26: ընդամենը | L26: միավորի գին | M26: քանակ | N26: ընդամենը | O26: միավորի գին | P26: քանակ | Q26: ընդամենը | R26: միավորի գին | S26: քանակ | T26: ընդամենը | U26: միավորի գին | V26: քանակ | W26: ընդամենը | X26: միավորի գին | Y26: քանակ | Z26: ընդամենը | AA26: միավորի գին | AB26: քանակ | AC26: ընդամենը | AD26: միավորի գին | AE26: քանակ | AF26: ընդամենը | AG26: միավորի գին | AH26: քանակ | AI26: ընդամենը | AJ26: միավորի գին | AK26: քանակ | AL26: ընդամենը | AM26: միավորի գին | AN26: քանակ | AO26: ընդամենը
A27: 2 | B27: Մետաքսե բարձի երես | C27: 27 500,00 | D27: 18,00 | E27: 495 000,00 | F27: 27 500,00 | G27: 35,00 | H27: 962 500,00 | I27: 27 500,00 | J27: 60,00 | K27: 1 650 000,00 | L27: 27 500,00 | M27: 42,00 | N27: 1 155 000,00 | O27: 27 500,00 | P27: 30,00 | Q27: 825 000,00 | R27: 27 500,00 | S27: 35,00 | T27: 962 500,00 | U27: 27 500,00 | V27: 40,00 | W27: 1 100 000,00 | X27: 27 500,00 | Y27: 36,00 | Z27: 990 000,00 | AA27: 27 500,00 | AB27: 42,00 | AC27: 1 155 000,00 | AD27: 27 500,00 | AE27: 48,00 | AF27: 1 320 000,00 | AG27: 27 500,00 | AH27: 65,00 | AI27: 1 787 500,00 | AJ27: 27 500,00 | AK27: 90,00 | AL27: 2 475 000,00 | AM27: 27 500,00 | AN27: 541,00 | AO27: 14 877 500,00
A28: 3 | B28: Մետաքսե քնի դիմակ | C28: 11 000,00 | D28: 24,00 | E28: 264 000,00 | F28: 11 000,00 | G28: 55,00 | H28: 605 000,00 | I28: 11 000,00 | J28: 80,00 | K28: 880 000,00 | L28: 11 000,00 | M28: 55,00 | N28: 605 000,00 | O28: 11 000,00 | P28: 42,00 | Q28: 462 000,00 | R28: 11 000,00 | S28: 50,00 | T28: 550 000,00 | U28: 11 000,00 | V28: 55,00 | W28: 605 000,00 | X28: 11 000,00 | Y28: 48,00 | Z28: 528 000,00 | AA28: 11 000,00 | AB28: 60,00 | AC28: 660 000,00 | AD28: 11 000,00 | AE28: 65,00 | AF28: 715 000,00 | AG28: 11 000,00 | AH28: 90,00 | AI28: 990 000,00 | AJ28: 11 000,00 | AK28: 125,00 | AL28: 1 375 000,00 | AM28: 11 000,00 | AN28: 749,00 | AO28: 8 239 000,00
A29: 4 | B29: Մետաքսե մազակալ | C29: 5 500,00 | D29: 42,00 | E29: 231 000,00 | F29: 5 500,00 | G29: 80,00 | H29: 440 000,00 | I29: 5 500,00 | J29: 120,00 | K29: 660 000,00 | L29: 5 500,00 | M29: 75,00 | N29: 412 500,00 | O29: 5 500,00 | P29: 65,00 | Q29: 357 500,00 | R29: 5 500,00 | S29: 72,00 | T29: 396 000,00 | U29: 5 500,00 | V29: 80,00 | W29: 440 000,00 | X29: 5 500,00 | Y29: 70,00 | Z29: 385 000,00 | AA29: 5 500,00 | AB29: 90,00 | AC29: 495 000,00 | AD29: 5 500,00 | AE29: 100,00 | AF29: 550 000,00 | AG29: 5 500,00 | AH29: 135,00 | AI29: 742 500,00 | AJ29: 5 500,00 | AK29: 200,00 | AL29: 1 100 000,00 | AM29: 5 500,00 | AN29: 1 129,00 | AO29: 6 209 500,00
A30: 5 | B30: Մետաքսե խալաթ | C30: 65 000,00 | D30: 3,00 | E30: 195 000,00 | F30: 65 000,00 | G30: 10,00 | H30: 650 000,00 | I30: 65 000,00 | J30: 18,00 | K30: 1 170 000,00 | L30: 65 000,00 | M30: 8,00 | N30: 520 000,00 | O30: 65 000,00 | P30: 5,00 | Q30: 325 000,00 | R30: 65 000,00 | S30: 12,00 | T30: 780 000,00 | U30: 65 000,00 | V30: 8,00 | W30: 520 000,00 | X30: 65 000,00 | Y30: 6,00 | Z30: 390 000,00 | AA30: 65 000,00 | AB30: 7,00 | AC30: 455 000,00 | AD30: 65 000,00 | AE30: 8,00 | AF30: 520 000,00 | AG30: 65 000,00 | AH30: 15,00 | AI30: 975 000,00 | AJ30: 65 000,00 | AK30: 25,00 | AL30: 1 625 000,00 | AM30: 65 000,00 | AN30: 125,00 | AO30: 8 125 000,00
A31: 6 | B31: Ասեղնագործություն | C31: 3 000,00 | D31: 8,00 | E31: 24 000,00 | F31: 3 000,00 | G31: 30,00 | H31: 90 000,00 | I31: 3 000,00 | J31: 50,00 | K31: 150 000,00 | L31: 3 000,00 | M31: 25,00 | N31: 75 000,00 | O31: 3 000,00 | P31: 15,00 | Q31: 45 000,00 | R31: 3 000,00 | S31: 25,00 | T31: 75 000,00 | U31: 3 000,00 | V31: 25,00 | W31: 75 000,00 | X31: 3 000,00 | Y31: 20,00 | Z31: 60 000,00 | AA31: 3 000,00 | AB31: 25,00 | AC31: 75 000,00 | AD31: 3 000,00 | AE31: 30,00 | AF31: 90 000,00 | AG31: 3 000,00 | AH31: 50,00 | AI31: 150 000,00 | AJ31: 3 000,00 | AK31: 80,00 | AL31: 240 000,00 | AM31: 3 000,00 | AN31: 383,00 | AO31: 1 149 000,00
A32: 7 | B32: ԸՆԴԱՄԵՆԸ | D32: 95,00 | E32: 1 209 000,00 | G32: 210,00 | H32: 2 747 500,00 | J32: 328,00 | K32: 4 510 000,00 | M32: 205,00 | N32: 2 767 500,00 | P32: 157,00 | Q32: 2 014 500,00 | S32: 194,00 | T32: 2 763 500,00 | V32: 208,00 | W32: 2 740 000,00 | Y32: 180,00 | Z32: 2 353 000,00 | AB32: 224,00 | AC32: 2 840 000,00 | AE32: 251,00 | AF32: 3 195 000,00 | AH32: 355,00 | AI32: 4 645 000,00 | AK32: 520,00 | AL32: 6 815 000,00 | AN32: 2 927,00 | AO32: 38 600 000,00
B34: Նշել ընկերության անունը
B35: Վաճառքի կանխատեսում 2017թ.
A36: հ/հ | B36: Համախառն վաճառք | C36: Հունվար | F36: Փետրվար | I36: Մարտ | L36: Ապրիլ | O36: Մայիս | R36: Հունիս | U36: Հուլիս | X36: Օգոստոս | AA36: Սեպտեմբեր | AD36: Հոկտեմբեր | AG36: Նոյեմբեր | AJ36: Դեկտեմբեր | AM36: ՀԱՆՐԱԳՈՒՄԱՐ
A37: 1 | C37: միավորի գին | D37: քանակ | E37: ընդամենը | F37: միավորի գին | G37: քանակ | H37: ընդամենը | I37: միավորի գին | J37: քանակ | K37: ընդամենը | L37: միավորի գին | M37: քանակ | N37: ընդամենը | O37: միավորի գին | P37: քանակ | Q37: ընդամենը | R37: միավորի գին | S37: քանակ | T37: ընդամենը | U37: միավորի գին | V37: քանակ | W37: ընդամենը | X37: միավորի գին | Y37: քանակ | Z37: ընդամենը | AA37: միավորի գին | AB37: քանակ | AC37: ընդամենը | AD37: միավորի գին | AE37: քանակ | AF37: ընդամենը | AG37: միավորի գին | AH37: քանակ | AI37: ընդամենը | AJ37: միավորի գին | AK37: քանակ | AL37: ընդամենը | AM37: միավորի գին | AN37: քանակ | AO37: ընդամենը
A38: 2 | B38: Մետաքսե բարձի երես | C38: 30 000,00 | D38: 21,00 | E38: 630 000,00 | F38: 30 000,00 | G38: 40,00 | H38: 1 200 000,00 | I38: 30 000,00 | J38: 69,00 | K38: 2 070 000,00 | L38: 30 000,00 | M38: 48,00 | N38: 1 440 000,00 | O38: 30 000,00 | P38: 35,00 | Q38: 1 050 000,00 | R38: 30 000,00 | S38: 40,00 | T38: 1 200 000,00 | U38: 30 000,00 | V38: 46,00 | W38: 1 380 000,00 | X38: 30 000,00 | Y38: 41,00 | Z38: 1 230 000,00 | AA38: 30 000,00 | AB38: 48,00 | AC38: 1 440 000,00 | AD38: 30 000,00 | AE38: 55,00 | AF38: 1 650 000,00 | AG38: 30 000,00 | AH38: 75,00 | AI38: 2 250 000,00 | AJ38: 30 000,00 | AK38: 104,00 | AL38: 3 120 000,00 | AM38: 30 000,00 | AN38: 622,00 | AO38: 18 660 000,00
A39: 3 | B39: Մետաքսե քնի դիմակ | C39: 12 000,00 | D39: 28,00 | E39: 336 000,00 | F39: 12 000,00 | G39: 63,00 | H39: 756 000,00 | I39: 12 000,00 | J39: 92,00 | K39: 1 104 000,00 | L39: 12 000,00 | M39: 63,00 | N39: 756 000,00 | O39: 12 000,00 | P39: 48,00 | Q39: 576 000,00 | R39: 12 000,00 | S39: 58,00 | T39: 696 000,00 | U39: 12 000,00 | V39: 63,00 | W39: 756 000,00 | X39: 12 000,00 | Y39: 55,00 | Z39: 660 000,00 | AA39: 12 000,00 | AB39: 69,00 | AC39: 828 000,00 | AD39: 12 000,00 | AE39: 75,00 | AF39: 900 000,00 | AG39: 12 000,00 | AH39: 104,00 | AI39: 1 248 000,00 | AJ39: 12 000,00 | AK39: 144,00 | AL39: 1 728 000,00 | AM39: 12 000,00 | AN39: 862,00 | AO39: 10 344 000,00
A40: 4 | B40: Մետաքսե մազակալ | C40: 5 500,00 | D40: 48,00 | E40: 264 000,00 | F40: 5 500,00 | G40: 92,00 | H40: 506 000,00 | I40: 5 500,00 | J40: 138,00 | K40: 759 000,00 | L40: 5 500,00 | M40: 86,00 | N40: 473 000,00 | O40: 5 500,00 | P40: 75,00 | Q40: 412 500,00 | R40: 5 500,00 | S40: 83,00 | T40: 456 500,00 | U40: 5 500,00 | V40: 92,00 | W40: 506 000,00 | X40: 5 500,00 | Y40: 80,00 | Z40: 440 000,00 | AA40: 5 500,00 | AB40: 104,00 | AC40: 572 000,00 | AD40: 5 500,00 | AE40: 115,00 | AF40: 632 500,00 | AG40: 5 500,00 | AH40: 155,00 | AI40: 852 500,00 | AJ40: 5 500,00 | AK40: 230,00 | AL40: 1 265 000,00 | AM40: 5 500,00 | AN40: 1 298,00 | AO40: 7 139 000,00
A41: 5 | B41: Մետաքսե խալաթ | C41: 80 000,00 | D41: 4,00 | E41: 320 000,00 | F41: 80 000,00 | G41: 12,00 | H41: 960 000,00 | I41: 80 000,00 | J41: 21,00 | K41: 1 680 000,00 | L41: 80 000,00 | M41: 9,00 | N41: 720 000,00 | O41: 80 000,00 | P41: 6,00 | Q41: 480 000,00 | R41: 80 000,00 | S41: 14,00 | T41: 1 120 000,00 | U41: 80 000,00 | V41: 9,00 | W41: 720 000,00 | X41: 80 000,00 | Y41: 7,00 | Z41: 560 000,00 | AA41: 80 000,00 | AB41: 8,00 | AC41: 640 000,00 | AD41: 80 000,00 | AE41: 9,00 | AF41: 720 000,00 | AG41: 80 000,00 | AH41: 17,00 | AI41: 1 360 000,00 | AJ41: 80 000,00 | AK41: 29,00 | AL41: 2 320 000,00 | AM41: 80 000,00 | AN41: 145,00 | AO41: 11 600 000,00
A42: 6 | B42: Ասեղնագործություն | C42: 3 000,00 | D42: 10,00 | E42: 30 000,00 | F42: 3 000,00 | G42: 35,00 | H42: 105 000,00 | I42: 3 000,00 | J42: 58,00 | K42: 174 000,00 | L42: 3 000,00 | M42: 29,00 | N42: 87 000,00 | O42: 3 000,00 | P42: 17,00 | Q42: 51 000,00 | R42: 3 000,00 | S42: 29,00 | T42: 87 000,00 | U42: 3 000,00 | V42: 29,00 | W42: 87 000,00 | X42: 3 000,00 | Y42: 23,00 | Z42: 69 000,00 | AA42: 3 000,00 | AB42: 29,00 | AC42: 87 000,00 | AD42: 3 000,00 | AE42: 35,00 | AF42: 105 000,00 | AG42: 3 000,00 | AH42: 58,00 | AI42: 174 000,00 | AJ42: 3 000,00 | AK42: 92,00 | AL42: 276 000,00 | AM42: 3 000,00 | AN42: 444,00 | AO42: 1 332 000,00
A43: 7 | B43: ԸՆԴԱՄԵՆԸ | D43: 111,00 | E43: 1 580 000,00 | G43: 242,00 | H43: 3 527 000,00 | J43: 378,00 | K43: 5 787 000,00 | M43: 235,00 | N43: 3 476 000,00 | P43: 181,00 | Q43: 2 569 500,00 | S43: 224,00 | T43: 3 559 500,00 | V43: 239,00 | W43: 3 449 000,00 | Y43: 206,00 | Z43: 2 959 000,00 | AB43: 258,00 | AC43: 3 567 000,00 | AE43: 289,00 | AF43: 4 007 500,00 | AH43: 409,00 | AI43: 5 884 500,00 | AK43: 599,00 | AL43: 8 709 000,00 | AN43: 3 371,00 | AO43: 49 075 000,00
...

Sheet Վաճ. կանխ. 2014-2018 գրաֆիկ

Sheet Շահույթի դինամիկա

Sheet Վաճ. ծավալի դինամիկա 2014-2018

Sheet Շահույթի հաշվարկ 2014
A1: Ընկերության անունը | D1: Շահույթի հաշվարկ առաջին տարվա համար | K1: Շահույթի հաշվարկ առաջին տարվա համար
A2: Ամիս | B2: Հունվար | C2: Փետրվար | D2: Մարտ | E2: Ապրիլ | F2: Մայիս | G2: Հունիս | H2: Հուլիս | I2: Օգոստոս | J2: Սեպտեմբեր | K2: Հոկտեմբեր | L2: Նոյեմբեր | M2: Դեկտեմբեր | N2: Ընդհանուր
A3: Վաճառքից հասույթ
A4: Բարձի երեսներ | B4: 125 000,00 դր. | C4: 375 000,00 դր. | D4: 1 000 000,00 դր. | E4: 625 000,00 դր. | F4: 500 000,00 դր. | G4: 550 000,00 դր. | H4: 625 000,00 դր. | I4: 625 000,00 դր. | J4: 750 000,00 դր. | K4: 875 000,00 դր. | L4: 1 125 000,00 դր. | M4: 1 500 000,00 դր. | N4: 8 675 000,00 դր.
A5: Քնի դիմակներ | B5: 50 000,00 դր. | C5: 100 000,00 դր. | D5: 500 000,00 դր. | E5: 350 000,00 դր. | F5: 250 000,00 դր. | G5: 300 000,00 դր. | H5: 350 000,00 դր. | I5: 300 000,00 դր. | J5: 400 000,00 դր. | K5: 450 000,00 դր. | L5: 600 000,00 դր. | M5: 850 000,00 դր. | N5: 4 500 000,00 դր.
A6: Մազակալներ | B6: 125 000,00 դր. | C6: 250 000,00 դր. | D6: 400 000,00 դր. | E6: 250 000,00 դր. | F6: 200 000,00 դր. | G6: 225 000,00 դր. | H6: 250 000,00 դր. | I6: 250 000,00 դր. | J6: 300 000,00 դր. | K6: 350 000,00 դր. | L6: 450 000,00 դր. | M6: 650 000,00 դր. | N6: 3 700 000,00 դր.
A7: Ընդհանուր վաճառք | B7: 300 000,00 դր. | C7: 725 000,00 դր. | D7: 1 900 000,00 դր. | E7: 1 225 000,00 դր. | F7: 950 000,00 դր. | G7: 1 075 000,00 դր. | H7: 1 225 000,00 դր. | I7: 1 175 000,00 դր. | J7: 1 450 000,00 դր. | K7: 1 675 000,00 դր. | L7: 2 175 000,00 դր. | M7: 3 000 000,00 դր. | N7: 16 875 000,00 դր.
A9: Ուղղակի ծախսեր
A10: Բարձի երեսի ինքնարժեք(կտոր + դերձակ + օժանդակ նյութեր) | B10: 72 500,00 դր. | C10: 217 500,00 դր. | D10: 580 000,00 դր. | E10: 362 500,00 դր. | F10: 290 000,00 դր. | G10: 319 000,00 դր. | H10: 362 500,00 դր. | I10: 362 500,00 դր. | J10: 435 000,00 դր. | K10: 507 500,00 դր. | L10: 652 500,00 դր. | M10: 870 000,00 դր.
A11: Քնի դիմակի ինքնարժեք | B11: 25 000,00 դր. | C11: 50 000,00 դր. | D11: 250 000,00 դր. | E11: 175 000,00 դր. | F11: 125 000,00 դր. | G11: 150 000,00 դր. | H11: 175 000,00 դր. | I11: 150 000,00 դր. | J11: 200 000,00 դր. | K11: 225 000,00 դր. | L11: 300 000,00 դր. | M11: 425 000,00 դր. | N11: 2 250 000,00 դր.
A12: Մազակալի ինքնարժեք | B12: 50 000,00 դր. | C12: 100 000,00 դր. | D12: 160 000,00 դր. | E12: 100 000,00 դր. | F12: 80 000,00 դր. | G12: 90 000,00 դր. | H12: 100 000,00 դր. | I12: 100 000,00 դր. | J12: 120 000,00 դր. | K12: 140 000,00 դր. | L12: 180 000,00 դր. | M12: 260 000,00 դր. | N12: 1 480 000,00 դր.
N13: 0,00 դր.
A14: Փաթեթավորում | B14: 24 500,00 դր. | C14: 52 500,00 դր. | D14: 119 000,00 դր. | E14: 77 000,00 դր. | F14: 59 500,00 դր. | G14: 67 900,00 դր. | H14: 77 000,00 դր. | I14: 73 500,00 դր. | J14: 91 000,00 դր. | K14: 105 000,00 դր. | L14: 136 500,00 դր. | M14: 192 500,00 դր. | N14: 1 075 900,00 դր.
N15: 0,00 դր.
N16: 0,00 դր.
N17: 0,00 դր.
N18: 0,00 դր.
B19: 0,00 դր. | C19: 0,00 դր. | D19: 0,00 դր. | E19: 0,00 դր. | F19: 0,00 դր. | G19: 0,00 դր. | H19: 0,00 դր. | I19: 0,00 դր. | J19: 0,00 դր. | K19: 0,00 դր. | N19: 0,00 դր.
A20: Ընդամենը ուղղակի ծախսեր | B20: 172 000,00 դր. | C20: 420 000,00 դր. | D20: 1 109 000,00 դր. | E20: 714 500,00 դր. | F20: 554 500,00 դր. | G20: 626 900,00 դր. | H20: 714 500,00 դր. | I20: 686 000,00 դր. | J20: 846 000,00 դր. | K20: 977 500,00 դր. | L20: 1 269 000,00 դր. | M20: 1 747 500,00 դր. | N20: 9 837 400,00 դր.
A22: Անուղղակի ծախսեր
A23: Տարածքի վարձ | B23: 150 000,00 դր. | C23: 150 000,00 դր. | D23: 150 000,00 դր. | E23: 150 000,00 դր. | F23: 150 000,00 դր. | G23: 150 000,00 դր. | H23: 150 000,00 դր. | I23: 150 000,00 դր. | J23: 150 000,00 դր. | K23: 150 000,00 դր. | L23: 150 000,00 դր. | M23: 150 000,00 դր. | N23: 1 800 000,00 դր.
A24: Գովազդ (Meta) | B24: 125 000,00 դր. | C24: 125 000,00 դր. | D24: 125 000,00 դր. | E24: 125 000,00 դր. | F24: 125 000,00 դր. | G24: 125 000,00 դր. | H24: 125 000,00 դր. | I24: 125 000,00 դր. | J24: 125 000,00 դր. | K24: 125 000,00 դր. | L24: 125 000,00 դր. | M24: 125 000,00 դր. | N24: 1 500 000,00 դր.
A25: SMM/օգնական | B25: 80 000,00 դր. | C25: 80 000,00 դր. | D25: 80 000,00 դր. | E25: 80 000,00 դր. | F25: 80 000,00 դր. | G25: 80 000,00 դր. | H25: 80 000,00 դր. | I25: 80 000,00 դր. | J25: 80 000,00 դր. | K25: 80 000,00 դր. | L25: 80 000,00 դր. | M25: 80 000,00 դր. | N25: 960 000,00 դր.
A26: Կոմունալ | B26: 25 000,00 դր. | C26: 25 000,00 դր. | D26: 25 000,00 դր. | E26: 22 000,00 դր. | F26: 20 000,00 դր. | G26: 20 000,00 դր. | H26: 20 000,00 դր. | I26: 20 000,00 դր. | J26: 20 000,00 դր. | K26: 22 000,00 դր. | L26: 28 000,00 դր. | M26: 35 000,00 դր. | N26: 282 000,00 դր.
A27: Գործառնական | B27: 40 000,00 դր. | C27: 40 000,00 դր. | D27: 45 000,00 դր. | E27: 40 000,00 դր. | F27: 40 000,00 դր. | G27: 40 000,00 դր. | H27: 40 000,00 դր. | I27: 40 000,00 դր. | J27: 45 000,00 դր. | K27: 45 000,00 դր. | L27: 50 000,00 դր. | M27: 60 000,00 դր. | N27: 525 000,00 դր.
A28: Ընդամենը անուղղակի ծախսեր | B28: 420 000,00 դր. | C28: 420 000,00 դր. | D28: 425 000,00 դր. | E28: 417 000,00 դր. | F28: 415 000,00 դր. | G28: 415 000,00 դր. | H28: 375 000,00 դր. | I28: 415 000,00 դր. | J28: 420 000,00 դր. | K28: 422 000,00 դր. | L28: 433 000,00 դր. | M28: 450 000,00 դր. | N28: 5 027 000,00 դր.
A30: Շահույթ մինչև հարկերի և տոկոսների վճարումը | B30: -292 000,00 դր. | C30: -115 000,00 դր. | D30: 366 000,00 դր. | E30: 93 500,00 դր. | F30: -19 500,00 դր. | G30: 33 100,00 դր. | H30: 135 500,00 դր. | I30: 74 000,00 դր. | J30: 184 000,00 դր. | K30: 275 500,00 դր. | L30: 473 000,00 դր. | M30: 802 500,00 դր. | N30: 2 417 600,00 դր.
A32: Վարկի տոկոսների վճարում | B32: 0,00 դր. | C32: 0,00 դր. | D32: 0,00 դր. | E32: 0,00 դր. | F32: 0,00 դր. | G32: 0,00 դր. | H32: 0,00 դր. | I32: 0,00 դր. | J32: 0,00 դր. | K32: 0,00 դր. | L32: 0,00 դր. | M32: 0,00 դր. | N32: 0,00 դր.
A34: Շահույթ մինչև հարկերի վճարումը | B34: -292 000,00 դր. | C34: -115 000,00 դր. | D34: 366 000,00 դր. | E34: 93 500,00 դր. | F34: -19 500,00 դր. | G34: 33 100,00 դր. | H34: 135 500,00 դր. | I34: 74 000,00 դր. | J34: 184 000,00 դր. | K34: 275 500,00 դր. | L34: 473 000,00 դր. | M34: 802 500,00 դր. | N34: 2 417 600,00 դր.
A36: Շահութահարկ | B36: -58 400,00 դր. | C36: -23 000,00 դր. | D36: 73 200,00 դր. | E36: 18 700,00 դր. | F36: -3 900,00 դր. | G36: 6 620,00 դր. | H36: 27 100,00 դր. | I36: 14 800,00 դր. | J36: 36 800,00 դր. | K36: 55 100,00 դր. | L36: 94 600,00 դր. | M36: 160 500,00 դր. | N36: 402 120,00 դր.
A37: Ամսական Զուտ Շահույթ | B37: -233 600,00 դր. | C37: -92 000,00 դր. | D37: 292 800,00 դր. | E37: 74 800,00 դր. | F37: -15 600,00 դր. | G37: 26 480,00 դր. | H37: 108 400,00 դր. | I37: 59 200,00 դր. | J37: 147 200,00 դր. | K37: 220 400,00 դր. | L37: 378 400,00 դր. | M37: 642 000,00 դր. | N37: 1 608 480,00 դր.

Sheet Շահույթի հաշվարկ 2015
A1: Ընկերության անունը | D1: Շահույթի հաշվարկ երկրորդ տարվա համար | K1: Շահույթի հաշվարկ երկրորդ տարվա համար
A2: Ամիս | B2: Հունվար | C2: Փետրվար | D2: Մարտ | E2: Ապրիլ | F2: Մայիս | G2: Հունիս | H2: Հուլիս | I2: Օգոստոս | J2: Սեպտեմբեր | K2: Հոկտեմբեր | L2: Նոյեմբեր | M2: Դեկտեմբեր | N2: Ընդհանուր
A3: Վաճառքից հասույթ
A4: Բարձի երեսներ | B4: 375 000,00 դր. | C4: 750 000,00 դր. | D4: 1 250 000,00 դր. | E4: 875 000,00 դր. | F4: 625 000,00 դր. | G4: 700 000,00 դր. | H4: 800 000,00 դր. | I4: 750 000,00 դր. | J4: 875 000,00 դր. | K4: 1 000 000,00 դր. | L4: 1 375 000,00 դր. | M4: 1 875 000,00 դր. | N4: 11 250 000,00 դր.
A5: Քնի դիմակներ | B5: 200 000,00 դր. | C5: 450 000,00 դր. | D5: 650 000,00 դր. | E5: 450 000,00 դր. | F5: 350 000,00 դր. | G5: 400 000,00 դր. | H5: 450 000,00 դր. | I5: 400 000,00 դր. | J5: 500 000,00 դր. | K5: 550 000,00 դր. | L5: 750 000,00 դր. | M5: 1 000 000,00 դր. | N5: 6 150 000,00 դր.
A6: Մազակալներ | B6: 175 000,00 դր. | C6: 325 000,00 դր. | D6: 500 000,00 դր. | E6: 300 000,00 դր. | F6: 275 000,00 դր. | G6: 300 000,00 դր. | H6: 325 000,00 դր. | I6: 300 000,00 դր. | J6: 375 000,00 դր. | K6: 425 000,00 դր. | L6: 550 000,00 դր. | M6: 800 000,00 դր. | N6: 4 650 000,00 դր.
A7: Ընդհանուր վաճառք | B7: 750 000,00 դր. | C7: 1 525 000,00 դր. | D7: 2 400 000,00 դր. | E7: 1 625 000,00 դր. | F7: 1 250 000,00 դր. | G7: 1 400 000,00 դր. | H7: 1 575 000,00 դր. | I7: 1 450 000,00 դր. | J7: 1 750 000,00 դր. | K7: 1 975 000,00 դր. | L7: 2 675 000,00 դր. | M7: 3 675 000,00 դր. | N7: 22 050 000,00 դր.
A9: Ուղղակի ծախսեր
A11: Բարձի երեսի ինքնարժեք(կտոր + դերձակ + օժանդակ նյութեր) | B11: 217 500,00 դր. | C11: 580 000,00 դր. | D11: 870 000,00 դր. | E11: 580 000,00 դր. | F11: 435 000,00 դր. | G11: 435 000,00 դր. | H11: 580 000,00 դր. | I11: 435 000,00 դր. | J11: 580 000,00 դր. | K11: 725 000,00 դր. | L11: 1 015 000,00 դր. | M11: 1 450 000,00 դր. | N11: 7 902 500,00 դր.
A12: Քնի դիմակի ինքնարժեք | B12: 100 000,00 դր. | C12: 200 000,00 դր. | D12: 350 000,00 դր. | E12: 250 000,00 դր. | F12: 200 000,00 դր. | G12: 300 000,00 դր. | H12: 250 000,00 դր. | I12: 300 000,00 դր. | J12: 300 000,00 դր. | K12: 300 000,00 դր. | L12: 400 000,00 դր. | M12: 500 000,00 դր. | N12: 3 450 000,00 դր.
B13: 317 500,00 դր. | C13: 780 000,00 դր. | D13: 1 220 000,00 դր. | E13: 830 000,00 դր. | F13: 635 000,00 դր. | G13: 735 000,00 դր. | H13: 830 000,00 դր. | I13: 735 000,00 դր. | J13: 880 000,00 դր. | K13: 1 025 000,00 դր. | L13: 1 415 000,00 դր. | M13: 1 950 000,00 դր. | N13: 11 352 500,00 դր.
A14: Մազակալի ինքնարժեք | B14: 70 000,00 դր. | C14: 90 000,00 դր. | D14: 150 000,00 դր. | E14: 100 000,00 դր. | F14: 80 000,00 դր. | G14: 80 000,00 դր. | H14: 80 000,00 դր. | I14: 100 000,00 դր. | J14: 120 000,00 դր. | K14: 110 000,00 դր. | L14: 130 000,00 դր. | M14: 170 000,00 դր. | N14: 1 280 000,00 դր.
A15: Փաթեթավորում | B15: 49 000,00 դր. | C15: 106 750,00 դր. | D15: 150 500,00 դր. | E15: 108 500,00 դր. | F15: 87 500,00 դր. | G15: 105 000,00 դր. | H15: 101 500,00 դր. | I15: 108 500,00 դր. | J15: 122 500,00 դր. | K15: 122 500,00 դր. | L15: 171 500,00 դր. | M15: 234 500,00 դր. | N15: 1 468 250,00 դր.
C16: 0,00 դր. | D16: 0,00 դր. | E16: 0,00 դր. | F16: 0,00 դր. | G16: 0,00 դր. | H16: 0,00 դր. | I16: 0,00 դր. | J16: 0,00 դր. | K16: 0,00 դր. | L16: 0,00 դր. | M16: 0,00 դր. | N16: 0,00 դր.
B17: 0,00 դր. | C17: 0,00 դր. | D17: 0,00 դր. | E17: 0,00 դր. | F17: 0,00 դր. | G17: 0,00 դր. | H17: 0,00 դր. | I17: 0,00 դր. | J17: 0,00 դր. | K17: 0,00 դր. | L17: 0,00 դր. | M17: 0,00 դր. | N17: 0,00 դր.
B18: 0,00 դր. | C18: 0,00 դր. | D18: 0,00 դր. | E18: 0,00 դր. | F18: 0,00 դր. | G18: 0,00 դր. | H18: 0,00 դր. | I18: 0,00 դր. | J18: 0,00 դր. | K18: 0,00 դր. | L18: 0,00 դր. | M18: 0,00 դր. | N18: 0,00 դր.
B19: 0,00 դր. | C19: 0,00 դր. | D19: 0,00 դր. | E19: 0,00 դր. | F19: 0,00 դր. | G19: 0,00 դր. | H19: 0,00 դր. | I19: 0,00 դր. | J19: 0,00 դր. | K19: 0,00 դր. | L19: 0,00 դր. | M19: 0,00 դր. | N19: 0,00 դր.
A20: Ընդամենը ուղղակի ծախսեր | B20: 436 500,00 դր. | C20: 976 750,00 դր. | D20: 1 520 500,00 դր. | E20: 1 038 500,00 դր. | F20: 802 500,00 դր. | G20: 920 000,00 դր. | H20: 1 011 500,00 դր. | I20: 943 500,00 դր. | J20: 1 122 500,00 դր. | K20: 1 257 500,00 դր. | L20: 1 716 500,00 դր. | M20: 2 354 500,00 դր. | N20: 14 100 750,00 դր.
A22: Անուղղակի ծախսեր
A23: Տարածքի վարձ | B23: 150 000,00 դր. | C23: 150 000,00 դր. | D23: 150 000,00 դր. | E23: 150 000,00 դր. | F23: 150 000,00 դր. | G23: 150 000,00 դր. | H23: 150 000,00 դր. | I23: 150 000,00 դր. | J23: 150 000,00 դր. | K23: 150 000,00 դր. | L23: 150 000,00 դր. | M23: 150 000,00 դր. | N23: 1 800 000,00 դր.
A24: Գովազդ (Meta) | B24: 150 000,00 դր. | C24: 150 000,00 դր. | D24: 150 000,00 դր. | E24: 150 000,00 դր. | F24: 150 000,00 դր. | G24: 150 000,00 դր. | H24: 150 000,00 դր. | I24: 150 000,00 դր. | J24: 150 000,00 դր. | K24: 150 000,00 դր. | L24: 150 000,00 դր. | M24: 150 000,00 դր. | N24: 1 800 000,00 դր.
A25: SMM/օգնական | B25: 100 000,00 դր. | C25: 100 000,00 դր. | D25: 100 000,00 դր. | E25: 100 000,00 դր. | F25: 100 000,00 դր. | G25: 100 000,00 դր. | H25: 100 000,00 դր. | I25: 100 000,00 դր. | J25: 100 000,00 դր. | K25: 100 000,00 դր. | L25: 100 000,00 դր. | M25: 100 000,00 դր. | N25: 1 200 000,00 դր.
A26: Կոմունալ | B26: 25 000,00 դր. | C26: 25 000,00 դր. | D26: 30 000,00 դր. | E26: 25 000,00 դր. | F26: 20 000,00 դր. | G26: 20 000,00 դր. | H26: 20 000,00 դր. | I26: 25 000,00 դր. | J26: 25 000,00 դր. | K26: 30 000,00 դր. | L26: 35 000,00 դր. | M26: 40 000,00 դր. | N26: 320 000,00 դր.
A27: Գործառնական | B27: 40 000,00 դր. | C27: 55 000,00 դր. | D27: 75 000,00 դր. | E27: 60 000,00 դր. | F27: 50 000,00 դր. | G27: 55 000,00 դր. | H27: 55 000,00 դր. | I27: 60 000,00 դր. | J27: 65 000,00 դր. | K27: 70 000,00 դր. | L27: 85 000,00 դր. | M27: 100 000,00 դր. | N27: 770 000,00 դր.
A28: Ընդամենը անուղղակի ծախսեր | B28: 425 000,00 դր. | C28: 425 000,00 դր. | D28: 430 000,00 դր. | E28: 425 000,00 դր. | F28: 420 000,00 դր. | G28: 420 000,00 դր. | H28: 420 000,00 դր. | I28: 425 000,00 դր. | J28: 425 000,00 դր. | K28: 430 000,00 դր. | L28: 435 000,00 դր. | M28: 440 000,00 դր. | N28: 5 120 000,00 դր.
A30: Շահույթ մինչև հարկերի և տոկոսների վճարումը | B30: -111 500,00 դր. | C30: 123 250,00 դր. | D30: 449 500,00 դր. | E30: 161 500,00 դր. | F30: 27 500,00 դր. | G30: 60 000,00 դր. | H30: 143 500,00 դր. | I30: 81 500,00 դր. | J30: 202 500,00 դր. | K30: 287 500,00 դր. | L30: 523 500,00 դր. | M30: 880 500,00 դր. | N30: 2 817 500,00 դր.
A32: Վարկի տոկոսների վճարում | B32: 0,00 դր. | C32: 0,00 դր. | D32: 0,00 դր. | E32: 0,00 դր. | F32: 0,00 դր. | G32: 0,00 դր. | H32: 0,00 դր. | I32: 0,00 դր. | J32: 0,00 դր. | K32: 0,00 դր. | L32: 0,00 դր. | M32: 0,00 դր. | N32: 0,00 դր.
A34: Շահույթ մինչև հարկերի վճարումը | B34: -111 500,00 դր. | C34: 123 250,00 դր. | D34: 449 500,00 դր. | E34: 161 500,00 դր. | F34: 27 500,00 դր. | G34: 60 000,00 դր. | H34: 143 500,00 դր. | I34: 81 500,00 դր. | J34: 202 500,00 դր. | K34: 287 500,00 դր. | L34: 523 500,00 դր. | M34: 880 500,00 դր. | N34: 2 817 500,00 դր.
A36: Շահութահարկ | B36: -22 300,00 դր. | C36: 24 650,00 դր. | D36: 89 900,00 դր. | E36: 32 300,00 դր. | F36: 5 500,00 դր. | G36: 12 000,00 դր. | H36: 28 700,00 դր. | I36: 16 300,00 դր. | J36: 40 500,00 դր. | K36: 57 500,00 դր. | L36: 104 700,00 դր. | M36: 176 100,00 դր. | N36: 565 850,00 դր.
A37: Ամսական Զուտ Շահույթ | B37: -89 200,00 դր. | C37: 98 600,00 դր. | D37: 359 600,00 դր. | E37: 129 200,00 դր. | F37: 22 000,00 դր. | G37: 48 000,00 դր. | H37: 114 800,00 դր. | I37: 65 200,00 դր. | J37: 162 000,00 դր. | K37: 230 000,00 դր. | L37: 418 800,00 դր. | M37: 704 400,00 դր. | N37: 2 263 400,00 դր.

Sheet Շահույթի հաշվարկ 2016
A1: Ընկերության անունը | D1: Շահույթի հաշվարկ երրորդ տարվա համար | K1: Շահույթի հաշվարկ երրորդ տարվա համար
A2: Ամիս | B2: Հունվար | C2: Փետրվար | D2: Մարտ | E2: Ապրիլ | F2: Մայիս | G2: Հունիս | H2: Հուլիս | I2: Օգոստոս | J2: Սեպտեմբեր | K2: Հոկտեմբեր | L2: Նոյեմբեր | M2: Դեկտեմբեր | N2: Ընդհանուր
A3: Վաճառքից հասույթ
A4: Մետաքսե բարձի երես | B4: 495 000,00 | C4: 962 500,00 | D4: 1 650 000,00 | E4: 1 155 000,00 | F4: 825 000,00 դր. | G4: 962 500,00 դր. | H4: 1 100 000,00 դր. | I4: 990 000,00 դր. | J4: 1 155 000,00 դր. | K4: 1 320 000,00 դր. | L4: 1 787 500,00 դր. | M4: 2 475 000,00 դր. | N4: 14 877 500,00 դր.
A5: Մետաքսե քնի դիմակ | B5: 264 000,00 | C5: 605 000,00 | D5: 880 000,00 | E5: 605 000,00 | F5: 462 000,00 դր. | G5: 550 000,00 դր. | H5: 605 000,00 դր. | I5: 528 000,00 դր. | J5: 660 000,00 դր. | K5: 715 000,00 դր. | L5: 990 000,00 դր. | M5: 1 375 000,00 դր. | N5: 8 239 000,00 դր.
A6: Մետաքսե մազակալ | B6: 231 000,00 | C6: 440 000,00 | D6: 660 000,00 | E6: 412 500,00 | F6: 357 500,00 դր. | G6: 396 000,00 դր. | H6: 440 000,00 դր. | I6: 385 000,00 դր. | J6: 495 000,00 դր. | K6: 550 000,00 դր. | L6: 742 500,00 դր. | M6: 1 100 000,00 դր. | N6: 6 209 500,00 դր.
A7: Մետաքսե խալաթ | B7: 195 000,00 | C7: 650 000,00 | D7: 1 170 000,00 | E7: 520 000,00 | F7: 325 000,00 դր. | G7: 780 000,00 դր. | H7: 520 000,00 դր. | I7: 390 000,00 դր. | J7: 455 000,00 դր. | K7: 520 000,00 դր. | L7: 975 000,00 դր. | M7: 1 625 000,00 դր. | N7: 8 125 000,00 դր.
A8: Ասեղնագործություն | B8: 24 000,00 | C8: 90 000,00 | D8: 150 000,00 | E8: 75 000,00 | F8: 45 000,00 դր. | G8: 75 000,00 դր. | H8: 75 000,00 դր. | I8: 60 000,00 դր. | J8: 75 000,00 դր. | K8: 90 000,00 դր. | L8: 150 000,00 դր. | M8: 240 000,00 դր. | N8: 1 149 000,00 դր.
A9: Ընդհանուր վաճառք | B9: 1 209 000,00 դր. | C9: 2 747 500,00 դր. | D9: 4 510 000,00 դր. | E9: 2 767 500,00 դր. | F9: 2 014 500,00 դր. | G9: 2 763 500,00 դր. | H9: 2 740 000,00 դր. | I9: 2 353 000,00 դր. | J9: 2 840 000,00 դր. | K9: 3 195 000,00 դր. | L9: 4 645 000,00 դր. | M9: 6 815 000,00 դր. | N9: 38 600 000,00 դր.
A11: Ուղղակի ծախսեր
A13: Բարձի երեսի ինքնարժեք(կտոր + դերձակ + օժանդակ նյութեր) | B13: 279 000,00 դր. | C13: 542 500,00 դր. | D13: 930 000,00 դր. | E13: 651 000,00 դր. | F13: 465 000,00 դր. | G13: 542 500,00 դր. | H13: 620 000,00 դր. | I13: 558 000,00 դր. | J13: 651 000,00 դր. | K13: 744 000,00 դր. | L13: 1 007 500,00 դր. | M13: 1 395 000,00 դր. | N13: 8 385 500,00 դր.
A14: Քնի դիմակի ինքնարժեք | B14: 132 000,00 դր. | C14: 302 500,00 դր. | D14: 440 000,00 դր. | E14: 302 500,00 դր. | F14: 275 000,00 դր. | G14: 396 000,00 դր. | H14: 302 500,00 դր. | I14: 385 000,00 դր. | J14: 440 000,00 դր. | K14: 495 000,00 դր. | L14: 605 000,00 դր. | M14: 687 500,00 դր. | N14: 4 763 000,00 դր.
A15: Մազակալի ինքնարժեք | B15: 92 400,00 դր. | C15: 176 000,00 դր. | D15: 264 000,00 դր. | E15: 165 000,00 դր. | F15: 143 000,00 դր. | G15: 158 400,00 դր. | H15: 158 400,00 դր. | I15: 154 000,00 դր. | J15: 198 000,00 դր. | K15: 220 000,00 դր. | L15: 297 000,00 դր. | M15: 440 000,00 դր. | N15: 2 466 200,00 դր.
A16: Մետաքսե խալաթի ինքնարժեք | B16: 105 000,00 դր. | C16: 350 000,00 դր. | D16: 630 000,00 դր. | E16: 280 000,00 դր. | F16: 175 000,00 դր. | G16: 420 000,00 դր. | H16: 420 000,00 դր. | I16: 210 000,00 դր. | J16: 210 000,00 դր. | K16: 280 000,00 դր. | L16: 525 000,00 դր. | M16: 875 000,00 դր. | N16: 4 480 000,00 դր.
A17: Ասնեղնագործություն | B17: 8 000,00 դր. | C17: 30 000,00 դր. | D17: 50 000,00 դր. | E17: 25 000,00 դր. | F17: 15 000,00 դր. | G17: 25 000,00 դր. | H17: 25 000,00 դր. | I17: 20 000,00 դր. | J17: 25 000,00 դր. | K17: 30 000,00 դր. | L17: 50 000,00 դր. | M17: 80 000,00 դր. | N17: 383 000,00 դր.
A18: Փաթեթավորում | B18: 95 000,00 դր. | C18: 210 000,00 դր. | D18: 328 000,00 դր. | E18: 205 000,00 դր. | F18: 157 000,00 դր. | G18: 194 000,00 դր. | H18: 208 000,00 դր. | I18: 180 000,00 դր. | J18: 224 000,00 դր. | K18: 251 000,00 դր. | L18: 355 000,00 դր. | M18: 520 000,00 դր. | N18: 2 927 000,00 դր.
B19: 0,00 դր. | C19: 0,00 դր. | D19: 0,00 դր. | E19: 0,00 դր. | F19: 0,00 դր. | G19: 0,00 դր. | H19: 0,00 դր. | I19: 0,00 դր. | J19: 0,00 դր. | K19: 0,00 դր. | L19: 0,00 դր. | M19: 0,00 դր. | N19: 0,00 դր.
B20: 0,00 դր. | C20: 0,00 դր. | D20: 0,00 դր. | E20: 0,00 դր. | F20: 0,00 դր. | G20: 0,00 դր. | H20: 0,00 դր. | I20: 0,00 դր. | J20: 0,00 դր. | K20: 0,00 դր. | L20: 0,00 դր. | M20: 0,00 դր. | N20: 0,00 դր.
A21: Ընդամենը ուղղակի ծախսեր | B21: 711 400,00 դր. | C21: 1 611 000,00 դր. | D21: 2 642 000,00 դր. | E21: 1 628 500,00 դր. | F21: 1 230 000,00 դր. | G21: 1 735 900,00 դր. | H21: 1 733 900,00 դր. | I21: 1 507 000,00 դր. | J21: 1 748 000,00 դր. | K21: 2 020 000,00 դր. | L21: 2 839 500,00 դր. | M21: 3 997 500,00 դր. | N21: 23 404 700,00 դր.
A23: Անուղղակի ծախսեր
A24: Տարածքի վարձ | B24: 200 000,00 դր. | C24: 200 000,00 դր. | D24: 200 000,00 դր. | E24: 200 000,00 դր. | F24: 200 000,00 դր. | G24: 200 000,00 դր. | H24: 200 000,00 դր. | I24: 200 000,00 դր. | J24: 200 000,00 դր. | K24: 200 000,00 դր. | L24: 200 000,00 դր. | M24: 200 000,00 դր. | N24: 2 400 000,00 դր.
A25: Գովազդ (Meta) | B25: 150 000,00 դր. | C25: 300 000,00 դր. | D25: 400 000,00 դր. | E25: 200 000,00 դր. | F25: 200 000,00 դր. | G25: 25 000,00 դր. | H25: 200 000,00 դր. | I25: 200 000,00 դր. | J25: 250 000,00 դր. | K25: 250 000,00 դր. | L25: 400 000,00 դր. | M25: 600 000,00 դր. | N25: 3 175 000,00 դր.
A26: SMM/օգնական | B26: 150 000,00 դր. | C26: 150 000,00 դր. | D26: 200 000,00 դր. | E26: 150 000,00 դր. | F26: 150 000,00 դր. | G26: 150 000,00 դր. | H26: 150 000,00 դր. | I26: 150 000,00 դր. | J26: 150 000,00 դր. | K26: 150 000,00 դր. | L26: 200 000,00 դր. | M26: 300 000,00 դր. | N26: 2 050 000,00 դր.
A27: Կոմունալ | B27: 50 000,00 դր. | C27: 50 000,00 դր. | D27: 45 000,00 դր. | E27: 35 000,00 դր. | F27: 30 000,00 դր. | G27: 30 000,00 դր. | H27: 30 000,00 դր. | I27: 35 000,00 դր. | J27: 35 000,00 դր. | K27: 40 000,00 դր. | L27: 50 000,00 դր. | M27: 60 000,00 դր. | N27: 490 000,00 դր.
A28: Գործառնական | B28: 50 000,00 դր. | C28: 60 000,00 դր. | D28: 100 000,00 դր. | E28: 60 000,00 դր. | F28: 50 000,00 դր. | G28: 60 000,00 դր. | H28: 60 000,00 դր. | I28: 50 000,00 դր. | J28: 60 000,00 դր. | K28: 60 000,00 դր. | L28: 100 000,00 դր. | M28: 150 000,00 դր. | N28: 860 000,00 դր.
A29: Ընդամենը անուղղակի ծախսեր | B29: 600 000,00 դր. | C29: 760 000,00 դր. | D29: 945 000,00 դր. | E29: 645 000,00 դր. | F29: 630 000,00 դր. | G29: 465 000,00 դր. | H29: 640 000,00 դր. | I29: 635 000,00 դր. | J29: 695 000,00 դր. | K29: 700 000,00 դր. | L29: 950 000,00 դր. | M29: 1 310 000,00 դր. | N29: 8 975 000,00 դր.
A31: Շահույթ մինչև հարկերի և տոկոսների վճարումը | B31: -102 400,00 դր. | C31: 376 500,00 դր. | D31: 923 000,00 դր. | E31: 494 000,00 դր. | F31: 154 500,00 դր. | G31: 562 600,00 դր. | H31: 366 100,00 դր. | I31: 211 000,00 դր. | J31: 397 000,00 դր. | K31: 475 000,00 դր. | L31: 855 500,00 դր. | M31: 1 507 500,00 դր. | N31: 5 946 200,00 դր.
A33: Վարկի տոկոսների վճարում | B33: 0,00 դր. | C33: 0,00 դր. | D33: 0,00 դր. | E33: 0,00 դր. | F33: 0,00 դր. | G33: 0,00 դր. | H33: 0,00 դր. | I33: 0,00 դր. | J33: 0,00 դր. | K33: 0,00 դր. | L33: 0,00 դր. | M33: 0,00 դր. | N33: 0,00 դր.
A35: Շահույթ մինչև հարկերի վճարումը | B35: -102 400,00 դր. | C35: 376 500,00 դր. | D35: 923 000,00 դր. | E35: 494 000,00 դր. | F35: 154 500,00 դր. | G35: 562 600,00 դր. | H35: 366 100,00 դր. | I35: 211 000,00 դր. | J35: 397 000,00 դր. | K35: 475 000,00 դր. | L35: 855 500,00 դր. | M35: 1 507 500,00 դր. | N35: 5 946 200,00 դր.
A37: Շահութահարկ | B37: -20 480,00 դր. | C37: 75 300,00 դր. | D37: 184 600,00 դր. | E37: 98 800,00 դր. | F37: 30 900,00 դր. | G37: 112 520,00 դր. | H37: 73 220,00 դր. | I37: 42 200,00 դր. | J37: 79 400,00 դր. | K37: 95 000,00 դր. | L37: 171 100,00 դր. | M37: 301 500,00 դր. | N37: 1 244 060,00 դր.
A38: Ամսական Զուտ Շահույթ | B38: -81 920,00 դր. | C38: 301 200,00 դր. | D38: 738 400,00 դր. | E38: 395 200,00 դր. | F38: 123 600,00 դր. | G38: 450 080,00 դր. | H38: 292 880,00 դր. | I38: 168 800,00 դր. | J38: 317 600,00 դր. | K38: 380 000,00 դր. | L38: 684 400,00 դր. | M38: 1 206 000,00 դր. | N38: 4 976 240,00 դր.

Sheet Շահույթի հաշվարկ 2017
A1: Ընկերության անունը | D1: Շահույթի հաշվարկ չորրորդ տարվա համար | K1: Շահույթի հաշվարկ չորրորդ տարվա համար
A2: Ամիս | B2: Հունվար | C2: Փետրվար | D2: Մարտ | E2: Ապրիլ | F2: Մայիս | G2: Հունիս | H2: Հուլիս | I2: Օգոստոս | J2: Սեպտեմբեր | K2: Հոկտեմբեր | L2: Նոյեմբեր | M2: Դեկտեմբեր | N2: Ընհանուր
A3: Վաճառքից հասույթ
A4: Մետաքսե բարձի երես | B4: 630 000,00 դր. | C4: 1 200 000,00 | D4: 2 070 000,00 դր. | E4: 1 440 000,00 դր. | F4: 1 050 000,00 | G4: 1 200 000,00 դր. | H4: 1 380 000,00 դր. | I4: 1 230 000,00 դր. | J4: 1 440 000,00 դր. | K4: 1 650 000,00 դր. | L4: 2 250 000,00 դր. | M4: 3 120 000,00 դր. | N4: 18 660 000,00 դր.
A5: Մետաքսե քնի դիմակ | B5: 336 000,00 դր. | C5: 756 000,00 | D5: 1 104 000,00 դր. | E5: 756 000,00 դր. | F5: 576 000,00 | G5: 696 000,00 դր. | H5: 756 000,00 դր. | I5: 660 000,00 դր. | J5: 828 000,00 դր. | K5: 900 000,00 դր. | L5: 1 248 000,00 դր. | M5: 1 728 000,00 դր. | N5: 10 344 000,00 դր.
A6: Մետաքսե մազակալ | B6: 264 000,00 դր. | C6: 506 000,00 | D6: 759 000,00 դր. | E6: 473 000,00 դր. | F6: 412 500,00 | G6: 456 500,00 դր. | H6: 506 000,00 դր. | I6: 440 000,00 դր. | J6: 572 000,00 դր. | K6: 632 500,00 դր. | L6: 852 500,00 դր. | M6: 1 265 000,00 դր. | N6: 7 139 000,00 դր.
A7: Մետաքսե խալաթ | B7: 320 000,00 դր. | C7: 960 000,00 | D7: 1 680 000,00 դր. | E7: 720 000,00 դր. | F7: 480 000,00 | G7: 1 120 000,00 դր. | H7: 720 000,00 դր. | I7: 560 000,00 դր. | J7: 640 000,00 դր. | K7: 720 000,00 դր. | L7: 1 360 000,00 դր. | M7: 2 320 000,00 դր. | N7: 11 600 000,00 դր.
A8: Ասեղնագործություն | B8: 30 000,00 դր. | C8: 105 000,00 | D8: 174 000,00 դր. | E8: 87 000,00 դր. | F8: 51 000,00 | G8: 87 000,00 դր. | H8: 87 000,00 դր. | I8: 69 000,00 դր. | J8: 87 000,00 դր. | K8: 105 000,00 դր. | L8: 174 000,00 դր. | M8: 276 000,00 դր. | N8: 1 332 000,00 դր.
A9: Ընդհանուր վաճառք | B9: 1 580 000,00 դր. | C9: 3 527 000,00 դր. | D9: 5 787 000,00 դր. | E9: 3 476 000,00 դր. | F9: 2 569 500,00 դր. | G9: 3 559 500,00 դր. | H9: 3 449 000,00 դր. | I9: 2 959 000,00 դր. | J9: 3 567 000,00 դր. | K9: 4 007 500,00 դր. | L9: 5 884 500,00 դր. | M9: 8 709 000,00 դր. | N9: 49 075 000,00 դր.
A11: Ուղղակի ծախսեր
A13: Բարձի երեսի ինքնարժեք(կտոր + դերձակ + օժանդակ նյութեր) | B13: 325 500,00 դր. | C13: 620 000,00 դր. | D13: 1 069 500,00 դր. | E13: 744 000,00 դր. | F13: 542 500,00 դր. | G13: 620 000,00 դր. | H13: 713 000,00 դր. | I13: 635 500,00 դր. | J13: 744 000,00 դր. | K13: 852 500,00 դր. | L13: 1 162 500,00 դր. | M13: 1 612 000,00 դր. | N13: 9 641 000,00 դր.
A14: Քնի դիմակի ինքնարժեք | B14: 154 000,00 դր. | C14: 346 500,00 դր. | D14: 506 000,00 դր. | E14: 346 500,00 դր. | F14: 264 000,00 դր. | G14: 319 000,00 դր. | H14: 346 500,00 դր. | I14: 302 500,00 դր. | J14: 374 000,00 դր. | K14: 412 500,00 դր. | L14: 572 000,00 դր. | M14: 792 000,00 դր. | N14: 4 735 500,00 դր.
A15: Մազակալի ինքնարժեք | B15: 105 600,00 դր. | C15: 202 400,00 դր. | D15: 303 600,00 դր. | E15: 189 200,00 դր. | F15: 165 000,00 դր. | G15: 182 600,00 դր. | H15: 204 600,00 դր. | I15: 176 000,00 դր. | J15: 228 800,00 դր. | K15: 253 000,00 դր. | L15: 341 000,00 դր. | M15: 506 000,00 դր. | N15: 2 857 800,00 դր.
A16: Մետաքսե խալաթի ինքնարժեք | B16: 140 000,00 դր. | C16: 420 000,00 դր. | D16: 735 000,00 դր. | E16: 315 000,00 դր. | F16: 210 000,00 դր. | G16: 490 000,00 դր. | H16: 315 000,00 դր. | I16: 245 000,00 դր. | J16: 280 000,00 դր. | K16: 315 000,00 դր. | L16: 595 000,00 դր. | M16: 1 015 000,00 դր. | N16: 5 075 000,00 դր.
A17: Ասնեղնագործություն | B17: 10 000,00 դր. | C17: 30 000,00 դր. | D17: 58 000,00 դր. | E17: 29 000,00 դր. | F17: 17 000,00 դր. | G17: 29 000,00 դր. | H17: 29 000,00 դր. | I17: 23 000,00 դր. | J17: 29 000,00 դր. | K17: 35 000,00 դր. | L17: 58 000,00 դր. | M17: 92 000,00 դր. | N17: 439 000,00 դր.
A18: Փաթեթավորում | B18: 111 000,00 դր. | C18: 242 000,00 դր. | D18: 378 000,00 դր. | E18: 235 000,00 դր. | F18: 181 000,00 դր. | G18: 224 000,00 դր. | H18: 239 000,00 դր. | I18: 206 000,00 դր. | J18: 258 000,00 դր. | K18: 289 000,00 դր. | L18: 409 000,00 դր. | M18: 599 000,00 դր. | N18: 3 371 000,00 դր.
A19: Արտադրական Կորուստ(2%) | B19: 31 600,00 դր. | C19: 70 540,00 դր. | D19: 115 740,00 դր. | E19: 69 520,00 դր. | F19: 51 390,00 դր. | G19: 71 190,00 դր. | H19: 68 980,00 դր. | I19: 59 180,00 դր. | J19: 71 340,00 դր. | K19: 80 150,00 դր. | L19: 117 690,00 դր. | M19: 174 180,00 դր. | N19: 981 500,00 դր.
B20: 0,00 դր. | C20: 0,00 դր. | D20: 0,00 դր. | E20: 0,00 դր. | F20: 0,00 դր. | G20: 0,00 դր. | H20: 0,00 դր. | I20: 0,00 դր. | J20: 0,00 դր. | K20: 0,00 դր. | L20: 0,00 դր. | M20: 0,00 դր. | N20: 0,00 դր.
A21: Ընդամենը ուղղակի ծախսեր | B21: 877 700,00 դր. | C21: 1 931 440,00 դր. | D21: 3 165 840,00 դր. | E21: 1 928 220,00 դր. | F21: 1 430 890,00 դր. | G21: 1 935 790,00 դր. | H21: 1 916 080,00 դր. | I21: 1 647 180,00 դր. | J21: 1 985 140,00 դր. | K21: 2 237 150,00 դր. | L21: 3 255 190,00 դր. | M21: 4 790 180,00 դր. | N21: 27 100 800,00 դր.
A23: Անուղղակի ծախսեր
A24: Տարածքի վարձ | B24: 220 000,00 դր. | C24: 220 000,00 դր. | D24: 220 000,00 դր. | E24: 220 000,00 դր. | F24: 220 000,00 դր. | G24: 220 000,00 դր. | H24: 220 000,00 դր. | I24: 220 000,00 դր. | J24: 220 000,00 դր. | K24: 220 000,00 դր. | L24: 220 000,00 դր. | M24: 220 000,00 դր. | N24: 2 640 000,00 դր.
A25: Գովազդ (Meta) | B25: 250 000,00 դր. | C25: 300 000,00 դր. | D25: 500 000,00 դր. | E25: 300 000,00 դր. | F25: 250 000,00 դր. | G25: 350 000,00 դր. | H25: 250 000,00 դր. | I25: 250 000,00 դր. | J25: 350 000,00 դր. | K25: 300 000,00 դր. | L25: 350 000,00 դր. | M25: 500 000,00 դր. | N25: 3 950 000,00 դր.
A26: SMM/օգնական | B26: 180 000,00 դր. | C26: 180 000,00 դր. | D26: 250 000,00 դր. | E26: 180 000,00 դր. | F26: 180 000,00 դր. | G26: 200 000,00 դր. | H26: 180 000,00 դր. | I26: 180 000,00 դր. | J26: 200 000,00 դր. | K26: 200 000,00 դր. | L26: 280 000,00 դր. | M26: 400 000,00 դր. | N26: 2 610 000,00 դր.
A27: Կոմունալ | B27: 55 000,00 դր. | C27: 55 000,00 դր. | D27: 65 000,00 դր. | E27: 45 000,00 դր. | F27: 40 000,00 դր. | G27: 45 000,00 դր. | H27: 40 000,00 դր. | I27: 45 000,00 դր. | J27: 45 000,00 դր. | K27: 50 000,00 դր. | L27: 60 000,00 դր. | M27: 75 000,00 դր. | N27: 620 000,00 դր.
A28: Գործառնական | B28: 70 000,00 դր. | C28: 90 000,00 դր. | D28: 120 000,00 դր. | E28: 80 000,00 դր. | F28: 70 000,00 դր. | G28: 90 000,00 դր. | H28: 70 000,00 դր. | I28: 70 000,00 դր. | J28: 85 000,00 դր. | K28: 95 000,00 դր. | L28: 130 000,00 դր. | M28: 180 000,00 դր. | N28: 1 150 000,00 դր.
A29: Սարք. սպասարկում | B29: 15 000,00 դր. | C29: 15 000,00 դր. | D29: 15 000,00 դր. | E29: 15 000,00 դր. | F29: 15 000,00 դր. | G29: 15 000,00 դր. | H29: 15 000,00 դր. | I29: 15 000,00 դր. | J29: 15 000,00 դր. | K29: 15 000,00 դր. | L29: 15 000,00 դր. | M29: 15 000,00 դր. | N29: 180 000,00 դր.
A30: Ընդամենը անուղղակի ծախսեր | B30: 790 000,00 դր. | C30: 860 000,00 դր. | D30: 1 170 000,00 դր. | E30: 840 000,00 դր. | F30: 775 000,00 դր. | G30: 920 000,00 դր. | H30: 775 000,00 դր. | I30: 780 000,00 դր. | J30: 915 000,00 դր. | K30: 880 000,00 դր. | L30: 1 055 000,00 դր. | M30: 1 390 000,00 դր. | N30: 11 150 000,00 դր.
A32: Շահույթ մինչև հարկերի և տոկոսների վճարումը | B32: -87 700,00 դր. | C32: 735 560,00 դր. | D32: 1 451 160,00 դր. | E32: 707 780,00 դր. | F32: 363 610,00 դր. | G32: 703 710,00 դր. | H32: 757 920,00 դր. | I32: 531 820,00 դր. | J32: 666 860,00 դր. | K32: 890 350,00 դր. | L32: 1 574 310,00 դր. | M32: 2 528 820,00 դր. | N32: 10 176 340,00 դր.
A34: Վարկի տոկոսների վճարում | B34: 0,00 դր. | C34: 0,00 դր. | D34: 0,00 դր. | E34: 0,00 դր. | F34: 0,00 դր. | G34: 0,00 դր. | H34: 0,00 դր. | I34: 0,00 դր. | J34: 0,00 դր. | K34: 0,00 դր. | L34: 0,00 դր. | M34: 0,00 դր. | N34: 0,00 դր.
A36: Շահույթ մինչև հարկերի վճարումը | B36: -87 700,00 դր. | C36: 735 560,00 դր. | D36: 1 451 160,00 դր. | E36: 707 780,00 դր. | F36: 363 610,00 դր. | G36: 703 710,00 դր. | H36: 757 920,00 դր. | I36: 531 820,00 դր. | J36: 666 860,00 դր. | K36: 890 350,00 դր. | L36: 1 574 310,00 դր. | M36: 2 528 820,00 դր. | N36: 10 176 340,00 դր.
A38: Շահութահարկ | B38: -17 540,00 դր. | C38: 147 112,00 դր. | D38: 290 232,00 դր. | E38: 141 556,00 դր. | F38: 72 722,00 դր. | G38: 140 742,00 դր. | H38: 151 584,00 դր. | I38: 106 364,00 դր. | J38: 133 372,00 դր. | K38: 178 070,00 դր. | L38: 314 862,00 դր. | M38: 505 764,00 դր. | N38: 2 164 840,00 դր.
A39: Ամսական Զուտ Շահույթ | B39: -70 160,00 դր. | C39: 588 448,00 դր. | D39: 1 160 928,00 դր. | E39: 566 224,00 դր. | F39: 290 888,00 դր. | G39: 562 968,00 դր. | H39: 606 336,00 դր. | I39: 425 456,00 դր. | J39: 533 488,00 դր. | K39: 712 280,00 դր. | L39: 1 259 448,00 դր. | M39: 2 023 056,00 դր. | N39: 8 659 360,00 դր.

Sheet Շահույթի հաշվարկ 2018
A1: Ընկերության անունը | D1: Շահույթի հաշվարկ հինգերորդ տարվա համար | K1: Շահույթի հաշվարկ հինգերորդ տարվա համար
A2: Ամիս | B2: Հունվար | C2: Փետրվար | D2: Մարտ | E2: Ապրիլ | F2: Մայիս | G2: Հունիս | H2: Հուլիս | I2: Օգոստոս | J2: Սեպտեմբեր | K2: Հոկտեմբեր | L2: Նոյեմբեր | M2: Դեկտեմբեր | N2: Ընդհանոուր
A3: Վաճառքից հասույթ
A4: Մետաքսե բարձի երես | B4: 805 000,00 դր. | C4: 1 540 000,00 դր. | D4: 2 660 000,00 դր. | E4: 1 855 000,00 դր. | F4: 1 365 000,00 դր. | G4: 1 540 000,00 դր. | H4: 1 785 000,00 դր. | I4: 1 575 000,00 դր. | J4: 1 855 000,00 դր. | K4: 2 135 000,00 դր. | L4: 2 905 000,00 դր. | M4: 3 990 000,00 դր. | N4: 24 010 000,00 դր.
A5: Մետաքսե քնի դիմակ | B5: 465 000,00 դր. | C5: 1 035 000,00 դր. | D5: 1 515 000,00 դր. | E5: 1 035 000,00 դր. | F5: 795 000,00 դր. | G5: 960 000,00 դր. | H5: 1 035 000,00 դր. | I5: 915 000,00 դր. | J5: 1 140 000,00 դր. | K5: 1 245 000,00 դր. | L5: 1 710 000,00 դր. | M5: 2 370 000,00 դր. | N5: 14 220 000,00 դր.
A6: Մետաքսե մազակալ | B6: 371 000,00 դր. | C6: 707 000,00 դր. | D6: 1 064 000,00 դր. | E6: 665 000,00 դր. | F6: 581 000,00 դր. | G6: 637 000,00 դր. | H6: 707 000,00 դր. | I6: 616 000,00 դր. | J6: 798 000,00 դր. | K6: 889 000,00 դր. | L6: 1 197 000,00 դր. | M6: 1 771 000,00 դր. | N6: 10 003 000,00 դր.
A7: Մետաքսե խալաթ | B7: 380 000,00 դր. | C7: 1 235 000,00 դր. | D7: 2 185 000,00 դր. | E7: 950 000,00 դր. | F7: 665 000,00 դր. | G7: 1 425 000,00 դր. | H7: 950 000,00 դր. | I7: 760 000,00 դր. | J7: 855 000,00 դր. | K7: 950 000,00 դր. | L7: 1 805 000,00 դր. | M7: 3 040 000,00 դր. | N7: 15 200 000,00 դր.
A8: Ասեղնագործություն | B8: 88 000,00 դր. | C8: 312 000,00 դր. | D8: 512 000,00 դր. | E8: 256 000,00 դր. | F8: 152 000,00 դր. | G8: 256 000,00 դր. | H8: 256 000,00 դր. | I8: 200 000,00 դր. | J8: 256 000,00 դր. | K8: 312 000,00 դր. | L8: 512 000,00 դր. | M8: 808 000,00 դր. | N8: 3 920 000,00 դր.
A9: Ընդհանուր վաճառք | B9: 2 109 000,00 դր. | C9: 4 829 000,00 դր. | D9: 7 936 000,00 դր. | E9: 4 761 000,00 դր. | F9: 3 558 000,00 դր. | G9: 4 818 000,00 դր. | H9: 4 733 000,00 դր. | I9: 4 066 000,00 դր. | J9: 4 904 000,00 դր. | K9: 5 531 000,00 դր. | L9: 8 129 000,00 դր. | M9: 11 979 000,00 դր. | N9: 67 353 000,00 դր.
A11: Ուղղակի ծախսեր
A13: Բարձի երեսի ինքնարժեք | B13: 184 000,00 դր. | C13: 352 000,00 դր. | D13: 608 000,00 դր. | E13: 424 000,00 դր. | F13: 312 000,00 դր. | G13: 352 000,00 դր. | H13: 408 000,00 դր. | I13: 360 000,00 դր. | J13: 424 000,00 դր. | K13: 488 000,00 դր. | L13: 664 000,00 դր. | M13: 912 000,00 դր. | N13: 5 488 000,00 դր.
A14: Քնի դիմակի ինքնարժեք | B14: 93 000,00 դր. | C14: 207 000,00 դր. | D14: 303 000,00 դր. | E14: 207 000,00 դր. | F14: 159 000,00 դր. | G14: 192 000,00 դր. | H14: 207 000,00 դր. | I14: 183 000,00 դր. | J14: 228 000,00 դր. | K14: 249 000,00 դր. | L14: 342 000,00 դր. | M14: 474 000,00 դր. | N14: 2 844 000,00 դր.
A15: Մազակալի ինքնարժեք | B15: 42 400,00 դր. | C15: 80 800,00 դր. | D15: 121 600,00 դր. | E15: 76 000,00 դր. | F15: 66 400,00 դր. | G15: 72 800,00 դր. | H15: 80 800,00 դր. | I15: 70 400,00 դր. | J15: 60 800,00 դր. | K15: 66 400,00 դր. | L15: 91 200,00 դր. | M15: 136 800,00 դր. | N15: 966 400,00 դր.
A16: Մետաքսե խալաթի ինքնարժեք | B16: 100 000,00 դր. | C16: 325 000,00 դր. | D16: 575 000,00 դր. | E16: 250 000,00 դր. | F16: 175 000,00 դր. | G16: 375 000,00 դր. | H16: 250 000,00 դր. | I16: 200 000,00 դր. | J16: 225 000,00 դր. | K16: 250 000,00 դր. | L16: 475 000,00 դր. | M16: 800 000,00 դր. | N16: 4 000 000,00 դր.
A17: Ասնեղնագործություն | B17: 11 000,00 դր. | C17: 39 000,00 դր. | D17: 64 000,00 դր. | E17: 32 000,00 դր. | F17: 19 000,00 դր. | G17: 32 000,00 դր. | H17: 32 000,00 դր. | I17: 25 000,00 դր. | J17: 32 000,00 դր. | K17: 39 000,00 դր. | L17: 64 000,00 դր. | M17: 101 000,00 դր. | N17: 490 000,00 դր.
A18: Փաթեթավորում | B18: 12 200,00 դր. | C18: 26 600,00 դր. | D18: 41 600,00 դր. | E18: 25 900,00 դր. | F18: 20 100,00 դր. | G18: 24 600,00 դր. | H18: 26 300,00 դր. | I18: 22 700,00 դր. | J18: 28 400,00 դր. | K18: 32 000,00 դր. | L18: 45 100,00 դր. | M18: 65 800,00 դր. | N18: 371 300,00 դր.
A19: Արտադրական Կորուստ(5%) | B19: 22 130,00 դր. | C19: 51 520,00 դր. | D19: 85 660,00 դր. | E19: 50 745,00 դր. | F19: 37 575,00 դր. | G19: 52 420,00 դր. | H19: 50 205,00 դր. | I19: 42 055,00 դր. | J19: 49 910,00 դր. | K19: 56 220,00 դր. | L19: 84 065,00 դր. | M19: 124 480,00 դր. | N19: 706 985,00 դր.
B20: 0,00 դր. | C20: 0,00 դր. | D20: 0,00 դր. | E20: 0,00 դր. | F20: 0,00 դր. | G20: 0,00 դր. | H20: 0,00 դր. | I20: 0,00 դր. | J20: 0,00 դր. | K20: 0,00 դր. | L20: 0,00 դր. | M20: 0,00 դր. | N20: 0,00 դր.
A21: Ընդամենը ուղղակի ծախսեր | B21: 464 730,00 դր. | C21: 1 081 920,00 դր. | D21: 1 798 860,00 դր. | E21: 1 065 645,00 դր. | F21: 789 075,00 դր. | G21: 1 100 820,00 դր. | H21: 1 054 305,00 դր. | I21: 903 155,00 դր. | J21: 1 048 110,00 դր. | K21: 1 180 620,00 դր. | L21: 1 765 365,00 դր. | M21: 2 614 080,00 դր. | N21: 14 866 685,00 դր.
A23: Անուղղակի ծախսեր
A24: Տնօրենի աշխատավարձ | B24: 300 000,00 դր. | C24: 300 000,00 դր. | D24: 300 000,00 դր. | E24: 300 000,00 դր. | F24: 300 000,00 դր. | G24: 300 000,00 դր. | H24: 300 000,00 դր. | I24: 300 000,00 դր. | J24: 300 000,00 դր. | K24: 300 000,00 դր. | L24: 300 000,00 դր. | M24: 500 000,00 դր. | N24: 3 800 000,00 դր.
A25: Դերձակների աշխատավարձ(3) | B25: 600 000,00 դր. | C25: 600 000,00 դր. | D25: 600 000,00 դր. | E25: 600 000,00 դր. | F25: 600 000,00 դր. | G25: 600 000,00 դր. | H25: 600 000,00 դր. | I25: 600 000,00 դր. | J25: 600 000,00 դր. | K25: 600 000,00 դր. | L25: 600 000,00 դր. | M25: 800 000,00 դր. | N25: 7 400 000,00 դր.
A26: Վաճառքի/SMM մենեջեր | B26: 150 000,00 դր. | C26: 150 000,00 դր. | D26: 150 000,00 դր. | E26: 150 000,00 դր. | F26: 150 000,00 դր. | G26: 150 000,00 դր. | H26: 150 000,00 դր. | I26: 150 000,00 դր. | J26: 150 000,00 դր. | K26: 150 000,00 դր. | L26: 150 000,00 դր. | M26: 250 000,00 դր. | N26: 1 900 000,00 դր.
A27: Գովազդ (Հասույթի 5%) | B27: 105 450,00 դր. | C27: 241 450,00 դր. | D27: 396 800,00 դր. | E27: 238 050,00 դր. | F27: 177 900,00 դր. | G27: 240 900,00 դր. | H27: 236 650,00 դր. | I27: 203 300,00 դր. | J27: 245 200,00 դր. | K27: 276 550,00 դր. | L27: 406 450,00 դր. | M27: 598 950,00 դր. | N27: 3 367 650,00 դր.
A28: Կոմունալ | B28: 35 000,00 դր. | C28: 45 000,00 դր. | D28: 70 000,00 դր. | E28: 45 000,00 դր. | F28: 40 000,00 դր. | G28: 45 000,00 դր. | H28: 45 000,00 դր. | I28: 40 000,00 դր. | J28: 45 000,00 դր. | K28: 55 000,00 դր. | L28: 75 000,00 դր. | M28: 90 000,00 դր. | N28: 630 000,00 դր.
A29: Գործառնական | B29: 45 000,00 դր. | C29: 60 000,00 դր. | D29: 100 000,00 դր. | E29: 60 000,00 դր. | F29: 50 000,00 դր. | G29: 65 000,00 դր. | H29: 65 000,00 դր. | I29: 55 000,00 դր. | J29: 65 000,00 դր. | K29: 75 000,00 դր. | L29: 110 000,00 դր. | M29: 160 000,00 դր. | N29: 910 000,00 դր.
A30: Սարք. սպասարկում | B30: 10 000,00 դր. | C30: 15 000,00 դր. | D30: 40 000,00 դր. | E30: 15 000,00 դր. | F30: 15 000,00 դր. | G30: 15 000,00 դր. | H30: 10 000,00 դր. | I30: 15 000,00 դր. | J30: 20 000,00 դր. | K30: 25 000,00 դր. | L30: 50 000,00 դր. | M30: 50 000,00 դր. | N30: 280 000,00 դր.
A31: Տարածքի վարձակալություն | B31: 350 000,00 դր. | C31: 350 000,00 դր. | D31: 350 000,00 դր. | E31: 350 000,00 դր. | F31: 350 000,00 դր. | G31: 350 000,00 դր. | H31: 350 000,00 դր. | I31: 350 000,00 դր. | J31: 350 000,00 դր. | K31: 350 000,00 դր. | L31: 350 000,00 դր. | M31: 350 000,00 դր. | N31: 4 200 000,00 դր.
A32: Ընդամենը անուղղակի ծախսեր | B32: 1 595 450,00 դր. | C32: 1 761 450,00 դր. | D32: 2 006 800,00 դր. | E32: 1 758 050,00 դր. | F32: 1 682 900,00 դր. | G32: 1 765 900,00 դր. | H32: 1 756 650,00 դր. | I32: 1 713 300,00 դր. | J32: 1 775 200,00 դր. | K32: 1 831 550,00 դր. | L32: 2 041 450,00 դր. | M32: 2 798 950,00 դր. | N32: 22 487 650,00 դր.
A34: Շահույթ մինչև հարկերի և տոկոսների վճարումը | B34: 48 820,00 դր. | C34: 1 985 630,00 դր. | D34: 4 130 340,00 դր. | E34: 1 937 305,00 դր. | F34: 1 086 025,00 դր. | G34: 1 951 280,00 դր. | H34: 1 922 045,00 դր. | I34: 1 449 545,00 դր. | J34: 2 080 690,00 դր. | K34: 2 518 830,00 դր. | L34: 4 322 185,00 դր. | M34: 6 565 970,00 դր. | N34: 27 964 215,00 դր.
A36: Վարկի տոկոսների վճարում | B36: 0,00 դր. | C36: 0,00 դր. | D36: 0,00 դր. | E36: 0,00 դր. | F36: 0,00 դր. | G36: 0,00 դր. | H36: 0,00 դր. | I36: 0,00 դր. | J36: 0,00 դր. | K36: 0,00 դր. | L36: 0,00 դր. | M36: 0,00 դր. | N36: 0,00 դր.
A38: Շահույթ մինչև հարկերի վճարումը | B38: 48 820,00 դր. | C38: 1 985 630,00 դր. | D38: 4 130 340,00 դր. | E38: 1 937 305,00 դր. | F38: 1 086 025,00 դր. | G38: 1 951 280,00 դր. | H38: 1 922 045,00 դր. | I38: 1 449 545,00 դր. | J38: 2 080 690,00 դր. | K38: 2 518 830,00 դր. | L38: 4 322 185,00 դր. | M38: 6 565 970,00 դր. | N38: 27 964 215,00 դր.
... A41: Ամսական Զուտ Շահույթ | B41: 39 056,00 դր. | C41: 1 588 504,00 դր. | D41: 3 304 272,00 դր. | E41: 1 549 844,00 դր. | F41: 868 820,00 դր. | G41: 1 561 024,00 դր. | H41: 1 537 636,00 դր. | I41: 1 159 636,00 դր. | J41: 1 664 552,00 դր. | K41: 2 015 064,00 դր. | L41: 3 457 748,00 դր. | M41: 5 252 776,00 դր. | N41: 23 998 932,00 դր.

Sheet do not print
E3: PLEASE, DO NOT DELETE THIS PAGE
B12: Համախառն վաճառքի ծավալի ամսական դինամիկան հնգամյա ժամանակահատվածում
E14: ՀՈՒՆՎԱՐ | F14: ՓԵՏՐՎԱՐ | G14: ՄԱՐՏ | H14: ԱՊՐԻԼ | I14: ՄԱՅԻՍ | J14: ՀՈՒՆԻՍ | K14: ՀՈՒԼԻՍ | L14: ՕԳՈՍՏՈՍ | M14: ՍԵՊՏԵՄԲԵՐ | N14: ՀՈԿՏԵՄԲԵՐ | O14: ՆՈՅԵՄԲԵՐ | P14: ԴԵԿՏԵՄԲԵՐ.
B15: Համախառն վաճառք | E15: =SUM('Վաճառքի կանխատեսում 2014-2018'!C62:E62) -> 0 | F15: =SUM('Վաճառքի կանխատեսում 2014-2018'!F62:H62) -> 0 | G15: =SUM('Վաճառքի կանխատեսում 2014-2018'!I62:K62) -> 0 | H15: =SUM('Վաճառքի կանխատեսում 2014-2018'!L62:N62) -> 0 | I15: =SUM('Վաճառքի կանխատեսում 2014-2018'!O62:Q62) -> 0 | J15: =SUM('Վաճառքի կանխատեսում 2014-2018'!R62:T62) -> 0 | K15: =SUM('Վաճառքի կանխատեսում 2014-2018'!U62:W62) -> 0 | L15: =SUM('Վաճառքի կանխատեսում 2014-2018'!X62:Z62) -> 0 | M15: =SUM('Վաճառքի կանխատեսում 2014-2018'!AA62:AC62) -> 0 | N15: =SUM('Վաճառքի կանխատեսում 2014-2018'!AD62:AF62) -> 0 | O15: =SUM('Վաճառքի կանխատեսում 2014-2018'!AG62:AI62) -> 0 | P15: =SUM('Վաճառքի կանխատեսում 2014-2018'!AJ62:AL62) -> 0
B26: Շահույթի դինամիկա տարեկան
B29: 2014թ. | C29: =SUM('Շահույթի հաշվարկ 2014'!N36) -> 0
B30: 2015թ. | C30: =SUM('Շահույթի հաշվարկ 2015'!N36) -> 0
B31: 2016թ. | C31: =SUM('Շահույթի հաշվարկ 2016'!N36) -> 0
B32: 2017թ. | C32: =SUM('Շահույթի հաշվարկ 2017'!N36) -> 0
B33: 2018 | C33: =SUM('Շահույթի հաշվարկ 2018'!N36) -> 0
B37: Վաճառքի ծավալների դինամիկա 2014-2018
B38: 2014 | C38: =SUM('Շահույթի հաշվարկ 2014'!N7) -> 0
B39: 2015 | C39: =SUM('Շահույթի հաշվարկ 2015'!N7) -> 0
B40: 2016 | C40: =SUM('Շահույթի հաշվարկ 2016'!N7) -> 0
